Workbook

Sheet Cover
A31: Food_Lab
A34: Team X
B57: Team Member : | D57: 1 | E57: Cherry Phoo Phoo Khaing
D58: 2 | E58: Zaw Phyo Aung
D59: 3 | E59: Min Khant
D60: 4 | E60: Zayyar Htet
D61: 5 | E61: Aung Min Khant
D62: 6 | E62: Zarni Win Lwin
K63: Create Date | M63: 44555
K64: Update Date | M64: =NOW() -> 44662.727
D101: T_CU_Coin
C104: customer_id | D104: Customer ID
C105: coin | D105: Coin Balance
C106: approve_By | D106: Approve By

Sheet Customer Requirement
A1: Customer Requirement (要件定義) | C1: =Cover!A31 -> Food_Lab | O1: Create Date | P1: 44555
O2: Update Date | P2: =NOW() -> 44662.727
A5: Customer Requirement
C6: 1 | D6: Kitchen lab
D7: 1-1 | E7: Admin Page
E8: 1-1-1 | F8: Admin Page
F9: a) | G9: Login
F10: b) | G10: Transaction Manage
F11: c) | G11: Coin Manage | J11: Admin
F12: d) | G12: Finance Manage
F13: e) | G13: Product Manage
F14: f) | G14: Dashboard
D16: 2-1 | E16: Customer Page
E17: 2-1-1 | F17: Customer Page Inculde
F18: a) | G18: Login
F19: b) | G19: Buy Coin
F20: c) | G20: Buy Item
F21: d) | G21: Verify Mail
F22: e) | G22: Message/Notification
F23: f) | G23: Profile Setting
F24: g) | G24: Tracking
D26: 3-1 | E26: Kitchen Page
E27: 3-1-1 | F27: Kitchen Page Include
F28: a) | G28: Order Manage

Sheet Schedule
A1: Schedule (進捗） | C1: =Cover!A31 -> Food_Lab | M1: Create Date | N1: 44555
M2: Update Date | N2: =NOW() -> 44662.727
C4: No | D4: Sub | E4: Task | F4: Assign | G4: Est Start | H4: Est End | I4: Duration Day | J4: Act Start | K4: Act End | L4: Act Duration | M4: Work Done
C5: 1 | E5: Schedule（進捗） | F5: ALL | G5: 44557 | H5: 44647 | I5: =H5-G5 -> 90 | J5: 44556 | L5: =K5-J5 -> -44556 | M5: 0
C6: 2 | E6: Project Flow（流れ） | F6: Linn | G6: 44557 | H6: 44564 | I6: =H6-G6 -> 7 | J6: 44556 | K6: 44564 | L6: =K6-J6 -> 8 | M6: 1
C7: 3 | E7: Screen Design（画面設計） | F7: C,M,ZN | G7: 44564 | H7: 44571 | I7: =H7-G7 -> 7 | J7: 44557 | K7: 44570 | L7: =K7-J7 -> 13 | M7: 1
C8: 4 | E8: Database（DB設計書） | F8: Linn | G8: 44566 | H8: 44571 | I8: =H8-G8 -> 5 | J8: 44566 | K8: 44570 | L8: =K8-J8 -> 4 | M8: 1
C9: 5 | E9: Development（開発） | F9: ALL | G9: 44571 | H9: 44602 | I9: =H9-G9 -> 31 | J9: 44571 | L9: =K9-J9 -> -44571 | M9: =SUM(M10:M23)/14 -> 0.76785714
D10: 1 | E10: Home | F10: Min | G10: 44571 | H10: 44575 | I10: =H10-G10 -> 4 | J10: 44571 | L10: =K10-J10 -> -44571 | M10: 0.8
D11: 2 | E11: Product | F11: Cherry,Aung | G11: 44577 | H11: 44591 | I11: =H11-G11 -> 14 | J11: 44579 | L11: =K11-J11 -> -44579 | M11: 0.4
D12: 3 | E12: Buy Coin | F12: Zaw | G12: 44581 | H12: 44591 | I12: =H12-G12 -> 10 | J12: 44581 | L12: =K12-J12 -> -44581 | M12: 0.8
D13: 4 | E13: Access | F13: Min | G13: 44575 | H13: 44580 | I13: =H13-G13 -> 5 | J13: 44575 | L13: =K13-J13 -> -44575 | M13: 0.85
D14: 5 | E14: Inform | F14: Zayar | G14: 44571 | H14: 44576 | I14: =H14-G14 -> 5 | J14: 44584 | L14: =K14-J14 -> -44584 | M14: 0.8
D15: 6 | E15: Profile | F15: Zayar | G15: 44576 | H15: 44582 | I15: =H15-G15 -> 6 | J15: 44579 | L15: =K15-J15 -> -44579 | M15: 0.7
D16: 1 | E16: Access | F16: Min | G16: 44580 | H16: 44585 | I16: =H16-G16 -> 5 | J16: 44585 | L16: =K16-J16 -> -44585 | M16: 0.8
D17: 2 | E17: Dashboard | F17: Zarni | G17: 44571 | H17: 44574 | I17: =H17-G17 -> 3 | J17: 44571 | L17: =K17-J17 -> -44571 | M17: 0.8
D18: 3 | E18: Transaction | F18: Zarni | G18: 44574 | H18: 44580 | I18: =H18-G18 -> 6 | J18: 44571 | L18: =K18-J18 -> -44571 | M18: 0.8
D19: 4 | E19: Coin | F19: Linn | G19: 44581 | H19: 44591 | I19: =H19-G19 -> 10 | J19: 44578 | K19: 44579 | L19: =K19-J19 -> 1 | M19: 0.8
D20: 5 | E20: Customer | F20: Zarni | G20: 44580 | H20: 44585 | I20: =H20-G20 -> 5 | J20: 44571 | L20: =K20-J20 -> -44571 | M20: 0.8
D21: 6 | E21: Finance | F21: Cherry | G21: 44571 | H21: 44577 | I21: =H21-G21 -> 6 | J21: 44571 | L21: =K21-J21 -> -44571 | M21: 0.8
D22: 7 | E22: Product | F22: Aung | G22: 44571 | H22: 44581 | I22: =H22-G22 -> 10 | J22: 44576 | L22: =K22-J22 -> -44576 | M22: 0.8
D23: 8 | E23: Setting | F23: Zayar | G23: 44582 | H23: 44587 | I23: =H23-G23 -> 5 | J23: 44571 | L23: =K23-J23 -> -44571 | M23: 0.8
D24: 1 | E24: Access | F24: Linn | I24: =H24-G24 -> 0 | L24: =K24-J24 -> 0 | M24: 0
D25: 2 | E25: Order | F25: Linn | I25: =H25-G25 -> 0 | L25: =K25-J25 -> 0 | M25: 0
C26: 6 | E26: Unit Test（単体試験） | G26: 44602 | H26: 44612 | I26: =H26-G26 -> 10 | L26: =K26-J26 -> 0 | M26: 0
C27: 7 | E27: Integration Test（結合試験） | G27: 44612 | H27: 44617 | I27: =H27-G27 -> 5 | L27: =K27-J27 -> 0 | M27: 0
C28: 8 | E28: Hosting Dev | G28: 44617 | H28: 44623 | I28: =H28-G28 -> 6 | L28: =K28-J28 -> 0 | M28: 0
C29: 9 | E29: Hosting Public | G29: 44623 | H29: 44630 | I29: =H29-G29 -> 7 | L29: =K29-J29 -> 0 | M29: 0
C30: 10 | E30: Release | G30: 44265 | H30: 44275 | I30: =H30-G30 -> 10 | L30: =K30-J30 -> 0 | M30: 0
I31: =SUM(I6:I30) -> 182
H32: Month | I32: =I31/30 -> 6.0666667
D101: T_CU_Coin
C104: customer_id | D104: Customer ID
C105: coin | D105: Coin Balance
C106: approve_By | D106: Approve By

Sheet By person
A1: Schedule (進捗） | C1: =Cover!A31 -> Food_Lab | AJ1: Create Date | AK1: 44555
AJ2: Update Date | AK2: =NOW() -> 44662.727
B5: No | C5: Name | D5: 10 | E5: 11 | F5: 12 | G5: 13 | H5: 14 | I5: 15 | J5: 16 | K5: 17 | L5: 18 | M5: 19 | N5: 20 | O5: 21 | P5: 22 | Q5: 23 | R5: 24 | S5: 25 | T5: 26 | U5: 27 | V5: 28 | W5: 29 | X5: 30 | Y5: 31 | Z5: 1 | AA5: 2 | AB5: 3 | AC5: 4 | AD5: 5 | AE5: 6 | AF5: 7 | AG5: 8 | AH5: 9 | AI5: 10
B6: 1 | C6: Cherry | F6: Finance | P6: Product | Z6: Review & Repair
B7: 2 | C7: Min | F7: Home | J7: Access | O7: Access | T7: Mobile
B8: 3 | C8: Aung | H8: Product | R8: Product
B9: 4 | C9: Zaw/Linn | H9: Coin | S9: Coin
B10: 5 | C10: Zarni | E10: Dashboard | I10: Transaction | O10: Customer | T10: Mobile Design
B11: 6 | C11: Zayar | F11: Inform | K11: Profile | Q11: Setting | V11: Mobile
B12: 7 | C12: Linn

Sheet Coin & Order Flow
A1: Main Flow (プロジャック流れ） | C1: =Cover!A31 -> Food_Lab | S1: Create Date | T1: 44555
S2: Update Date | T2: =NOW() -> 44662.727
A4: Explanation of Project | D4: Coin & Order Flow
A5: プロジャックの説明
A10: (プロジャック流れ）
C13: Admin | K13: Customer | Q13: Kitchen
C24: No | E24: Yes
M33: Yes
K34: No
M42: COIN
N45: COD
C49: No | E49: Yes
D101: T_CU_Coin
C104: customer_id | D104: Customer ID
C105: coin | D105: Coin Balance
C106: approve_By | D106: Approve By

Sheet Project Flow_Admin
A1: Main Flow (プロジャック流れ） | C1: =Cover!A31 -> Food_Lab | O1: Create Date | P1: 44555
O2: Update Date | P2: =NOW() -> 44662.727
A4: Explanation of Project | D4: Admin Page
A5: プロジャックの説明
A10: (プロジャック流れ）
B13: Path： | C13: http:domain/admin/ | O13: Super Admin
O15: Main Category
O16: Function
O17: Page

Sheet Project Flow_Customer
A1: Main Flow (プロジャック流れ） | C1: =Cover!A31 -> Food_Lab | R1: Create Date | S1: 44555
R2: Update Date | S2: =NOW() -> 44662.727
A4: Explanation of Project | D4: Customer page (Home)
A5: プロジャックの説明
A10: (プロジャック流れ）
B13: Path： | C13: http:domain/

Sheet Project Flow_Kitchen
A1: Main Flow (プロジャック流れ） | C1: =Cover!A31 -> Food_Lab | S1: Create Date | T1: 44555
S2: Update Date | T2: =NOW() -> 44662.727
A4: Explanation of Project | D4: Kitchen Page
A5: プロジャックの説明
A10: (プロジャック流れ）
B13: Path： | C13: http:domain/order

Sheet Screen Design
A1: Screen Design (画面設計） | C1: =Cover!A31 -> Food_Lab | O1: Create Date | P1: 44555
O2: Update Date | P2: =NOW() -> 44662.727
A5: Screen Name ： | D5: Admin Login Screen

Sheet Code Rule
A1: Code Rule | C1: =Cover!A31 -> Food_Lab | O1: Create Date | P1: 44555
O2: Update Date | P2: =NOW() -> 44662.727
B5: Global Rule
C6: 1 | D6: Camel Naming Rule for all Function
C7: 2 | D7: Max Code line: 170 line in one method
C8: 3 | D8: Max Argument : 7 parameter in one function
C9: 4 | D9: ALL Capatial Letter for global variable
C10: 5 | D10: Variable name must be meaningful (Not allow x,y,x,I,etc…)
C11: 6 | D11: Must write comment in every method (header)
D12: /*
D13: *Create:Author Name(Date)
D14: *Update:Author Name(Date)
D15: *Explanation of method or function
D16: *Parameter explain
D17: *Return
D18: */
C19: 7 | D19: Not allow 3 time nested Loop Condition
C20: 8 | D20: If using recursive method,must have break condition
C21: 9 | D21: Must be format.
B23: HTML Rule
C24: 1 | D24: Must write close tag
C25: 2 | D25: Must write comment for open close tag
C26: 3 | D26: Not allow inline css and internal css
C27: 4 | D27: ID must be unique in one html
B29: CSS Rule
C30: 1 | D30: Use scale unit (em,%,vh,vw) instead of px.(As much as possible)
C31: 2 | D31: Use root declear for common properties.
C32: 3 | D32: Must write comment by block
C33: 4 | D33: Not allow minus assign (Example : margin : -10px)
C34: 5 | D34: Must be responsive
B36: Javascript/Jquery Rule
C37: 1 | D37: Global varible must be write in start of line
C38: 2 | D38: If webpage is used jquery,Must be write (document.ready…)
C39: 3 | D39: Avoid Deadcode
B41: Json Rule
C42: 1 | D42: Key must be meaningful
B44: Ajax Rule
C45: 1 | D45: Must have ContectType,success,error catch and statuscode control
C46: 2 | D46: Must have timeout properties
C47: 3 | D47: ID must be encrypt
...

Sheet DB Design
A1: DB Design (DB設計） | C1: =Cover!A31 -> Food_Lab | N1: Create Date | O1: 44555
N2: Update Date | O2: =NOW() -> 44662.727
B4: DB Name ： | D4: FOOD_LAB_DB
B6: Default Fields
B8: No | C8: Field Name | D8: Description | F8: PK | G8: AI | H8: NN | I8: Type | J8: Length | K8: FK | L8: Remark
B9: 1 | C9: id | D9: ID of Row | F9: ● | G9: ● | H9: ● | I9: Bigint
B10: 2 | C10: del_flg | D10: Deleted or Not | H10: ● | I10: integer | L10: 0:false , 1:true
B11: 3 | C11: created_at | D11: Created Timestamp | H11: ● | I11: timestamp
B12: 4 | C12: updated_at | D12: Updated Timestamp | I12: timestamp
B15: Table Name ： | D15: M_AD_Login
B17: No | C17: Field Name | D17: Description | F17: PK | G17: AI | H17: NN | I17: Type | J17: Length | K17: FK | L17: Remark
B18: 1 | C18: ad_name | D18: Name | H18: ● | I18: varchar | J18: 128
B19: 2 | C19: ad_password | D19: Password | H19: ● | I19: varchar | J19: 128
B20: 3 | C20: ad_role | D20: Role | H20: ● | I20: varchar | J20: 2 | L20: SA:Super Admin, AD:Admin, KA:Kitchen_Admin,DL:Delivery
B21: 4 | C21: ad_valid | D21: Valid or not | H21: ● | I21: integer | L21: 0:false , 1:true
B22: 5 | C22: ad_login_dt | D22: Last Login Time | I22: timestamp
B27: Table Name ： | D27: M_AD_CoinRate
B29: No | C29: Field Name | D29: Description | F29: PK | G29: AI | H29: NN | I29: Type | J29: Length | K29: FK | L29: Remark
B30: 1 | C30: base | D30: Base on coin | H30: ● | I30: integer | L30: Default is 1
B31: 2 | C31: rate | D31: Rate | H31: ● | I31: integer
B38: Table Name ： | D38: T_AD_CoinRate_History
B40: No | C40: Field Name | D40: Description | F40: PK | G40: AI | H40: NN | I40: Type | J40: Length | K40: FK | L40: Remark
B41: 1 | C41: old_base | D41: Old Base Coin | H41: ● | I41: integer | L41: Default is 1
B42: 2 | C42: new_base | D42: New Base Coin | H42: ● | I42: integer
B43: 3 | C43: old_rate | D43: Old Rate | H43: ● | I43: integer
B44: 4 | C44: new_rate | D44: New Rate | H44: ● | I44: integer
B45: 5 | C45: change_by | D45: Change By | H45: ● | I45: Bigint | K45: ● | L45: M_AD_Login ID
B46: 6 | C46: change_note | D46: Change reason or Description | H46: ● | I46: varchar
B50: Table Name ： | D50: T_AD_Order
B52: No | C52: Field Name | D52: Description | F52: PK | G52: AI | H52: NN | I52: Type | J52: Length | K52: FK | L52: Remark
B53: 1 | C53: customer_id | D53: Customer ID | H53: ● | I53: Bigint | K53: ● | L53: T_CU_Customer ID
B54: 2 | C54: payment | D54: Payment Type | H54: ● | I54: integer | L54: 0:Coin,1:COD
B55: 3 | C55: township_id | D55: Delivery Township ID | H55: ● | I55: integer | L55: M_Township ID
B56: 4 | C56: grandtotal_coin | D56: If Customer Buy with Coin | I56: integer | L56: Either or
B57: 5 | C57: grandtotal_cash | D57: If Customer Buy with COD | I57: integer
B58: 6 | C58: order_status | D58: Order Status | H58: ● | I58: integer | L58: M_Order_Status ID
B59: 7 | C59: order_date | D59: Order Date | H59: ● | I59: date
B60: 8 | C60: order_time | D60: Order Time | H60: ● | I60: time
B61: 9 | C61: last_control_by | D61: Last time Control By | H61: ● | I61: Bigint | K61: ● | L61: M_AD_Login ID
B65: Table Name ： | D65: T_AD_OrderDetail
...
